Workbook
Name Table: Main!$D:$U
Name Table: Map!$D:$M

Sheet Map
A1: Restaurant | B1: Featured in Episode: | C1: Price Point | D1: Season | E1: Episode | F1: Items ordered | G1: Restaurant Link | H1: Address | I1: Video Link | J1: Publish Date | K1: Chain? | L1: Votes | M1: Notes
A2: =HYPERLINK("http://www.hamasakula.com/","Hamasaku") -> Hamasaku | B2: $3 Sushi Vs. $250 Sushi | C2: $$ | D2: 1 | E2: 1 | F2: $18.00 - Kinmedai White Ponzu Nigiri Platter Cajun Crab Roll | G2: http://www.hamasakula.com/ | H2: 11043 CA-2, Los Angeles, CA 90025 | I2: http://www.youtube.com/watch?v=2GZrPR5Ajrs | J2: 42631 | K2: no | M2: Price per plate
A3: Sasabune | B3: $3 Sushi Vs. $250 Sushi | C3: $$$ | D3: 1 | E3: 1 | F3: $250.00 - Omakase | G3: https://g.page/sasabuneglendale?share | H3: 101 N Brand Blvd UNIT 220, Glendale, CA 91023 | I3: http://www.youtube.com/watch?v=2GZrPR5Ajrs | J3: 42631 | K3: yes | L3: 1 | M3: Dinner for two
A4: =HYPERLINK("https://sushistop.com/","Sushi Stop") -> Sushi Stop | B4: $3 Sushi Vs. $250 Sushi | C4: $ | D4: 1 | E4: 1 | F4: $4.00 - Bluefin Nigiri $6.00 - Spanish Mackerel $2.95 - Spicy Scallap Roll $2.95 - Sweet Shrimp Nigiri | G4: https://sushistop.com/ | H4: 2218 Sawtelle Blvd, Los Angeles, CA 90064 | I4: http://www.youtube.com/watch?v=2GZrPR5Ajrs | J4: 42631 | K4: yes | L4: 1
A5: =HYPERLINK("https://www.caesars.com/paris-las-vegas/restaurants/burger-brasserie","Burger Brasserie") -> Burger Brasserie | B5: $4 Burger Vs. $777 Burger | C5: $$$ | D5: 1 | E5: 2 | F5: $777.00 - 777 Burger | G5: https://www.caesars.com/paris-las-vegas/restaurants/burger-brasserie | H5: 3655 S Las Vegas Blvd, Las Vegas, NV 89109 | I5: http://www.youtube.com/watch?v=wduZHtRbSkY | J5: 42638 | K5: no | L5: 1
A6: =HYPERLINK("https://www.caesars.com/planet-hollywood/restaurants/ramsay","Gordon Ramsay Burger") -> Gordon Ramsay Burger | B6: $4 Burger Vs. $777 Burger | C6: $$ | D6: 1 | E6: 2 | F6: $18.00 - Hog Burger | G6: https://www.caesars.com/planet-hollywood/restaurants/ramsay | H6: 3667 S Las Vegas Blvd, Las Vegas, NV 89109 | I6: http://www.youtube.com/watch?v=wduZHtRbSkY | J6: 42638 | K6: no | L6: 1
A7: =HYPERLINK("https://www.habitburger.com/","Habit Burger") -> Habit Burger | B7: $4 Burger Vs. $777 Burger | C7: $ | D7: 1 | E7: 2 | F7: $4.15 - Double Charburger | G7: https://www.habitburger.com/ | H7: 4830 Blue Diamond Rd, Las Vegas, NV 89139 | I7: http://www.youtube.com/watch?v=wduZHtRbSkY | J7: 42638 | K7: yes
A8: =HYPERLINK("https://www.blazepizza.com/locations/los-angeles-usc/","Blaze Pizza") -> Blaze Pizza | B8: $5 Pizza Vs. $135 Pizza | C8: $ | D8: 1 | E8: 3 | F8: $7.95 - Green Stripe $5.25 - Simple Pie | G8: https://www.blazepizza.com/locations/los-angeles-usc/ | H8: 667 E Colorado Blvd, Pasadena, CA 91101 | I8: http://www.youtube.com/watch?v=vzSfnduxNDg | J8: 42645 | K8: yes
A9: =HYPERLINK("https://pizzeriamozza.com/","Pizzeria Mozza") -> Pizzeria Mozza | B9: $5 Pizza Vs. $135 Pizza | C9: $$ | D9: 1 | E9: 3 | F9: $23.00 - Squash Blossoms | G9: https://pizzeriamozza.com/ | H9: 641 N Highland Ave, Los Angeles, CA 90036 | I9: http://www.youtube.com/watch?v=vzSfnduxNDg | J9: 42645 | K9: no | L9: 2
A10: =HYPERLINK("www.wolfgangpuck.com/dining/spago/","Spago") -> Spago | B10: $5 Pizza Vs. $135 Pizza $4 Dessert Vs. $235 Dessert | C10: $$$ | D10: 1 10 | E10: 3 3 | F10: $135.00 - Italian Summer Truffle $235.00 - Dessert Tasting Menu Enlish Muffin with Sea Urchin $69.00 Keluga Caviar Rye Tart Hokkaido Scallop Ceviche Charred Sunchoke $39.00 Sautéed Maine Monkfish $52.00 Lacquered Liberty Farm's Duck Breast | G10: www.wolfgangpuck.com/dining/spago/ | H10: 176 N Canon Dr, Beverly Hills, CA 90210 | I10: http://www.youtube.com/watch?v=vzSfnduxNDg https://youtu.be/Bhos_P4a-JQ?t=854 | J10: 10/2/2016 12/11/2021 | K10: no | L10: 1 | M10: Desser Oyster, Hasselback Apple, Chestnut Souffle; non of these appear to be on the Spago menu
A11: =HYPERLINK("http://wolfgangpuck.com/dining/cut-beverly-hills/","CUT") -> CUT | B11: $11 Steak Vs. $306 Steak | C11: $$$ | D11: 1 | E11: 4 | F11: $306.00 - Japanese Pure Wagyu | G11: http://wolfgangpuck.com/dining/cut-beverly-hills/ | H11: 9500 Wilshire Blvd, Beverly Hills, CA 90212 | I11: http://www.youtube.com/watch?v=Z5FoX3ju2J0 | J11: 42659 | K11: no | L11: 1
A12: =HYPERLINK("https://www.patinagroup.com/nick-and-stefs-steakhouse-la","Nick & Stef's Steakhouse") -> Nick & Stef's Steakhouse | B12: $11 Steak Vs. $306 Steak | C12: $$ | D12: 1 | E12: 4 | F12: $72.00 - Dry-Aged Rib Eye | G12: https://www.patinagroup.com/nick-and-stefs-steakhouse-la | H12: 330 S Hope St, Los Angeles, CA 90071 | I12: http://www.youtube.com/watch?v=Z5FoX3ju2J0 | J12: 42659 | K12: no | L12: 1
A13: =HYPERLINK("https://unclejohnsdtla.com/","Uncle John's Cafe") -> Uncle John's Cafe | B13: $11 Steak Vs. $306 Steak | C13: $ | D13: 1 | E13: 4 | F13: $11.00 - Steak and Eggs | G13: https://unclejohnsdtla.com/ | H13: 834 S Grand Ave, Los Angeles, CA 90017 | I13: http://www.youtube.com/watch?v=Z5FoX3ju2J0 | J13: 42659 | K13: no | L13: 1
A14: =HYPERLINK("http://lepetitparisla.com/","Le Petit Paris") -> Le Petit Paris | B14: $8 Pasta Vs. $100 Pasta | C14: $$$ | D14: 1 | E14: 5 | F14: $100.00 - Flambeed White Truffle Pasta | G14: http://lepetitparisla.com/ | H14: 418 S Spring St, Los Angeles, CA 90013 | I14: http://www.youtube.com/watch?v=NHiqsrYkcuk | J14: 42673 | K14: no
A15: =HYPERLINK("https://www.osteriamamma.com/","Osteria Mamma") -> Osteria Mamma | B15: $8 Pasta Vs. $100 Pasta | C15: $$ | D15: 1 | E15: 5 | F15: $19.75 - Bigoli Neri Alla Bottarga $19.25 - Pappardelle All'anatra | G15: https://www.osteriamamma.com/ | H15: 5732 Melrose Ave, Hollywood, CA 90004 | I15: http://www.youtube.com/watch?v=NHiqsrYkcuk | J15: 42673 | K15: no
A16: =HYPERLINK("https://www.pastasisters.com/","Pasta Sisters") -> Pasta Sisters | B16: $8 Pasta Vs. $100 Pasta | C16: $ | D16: 1 | E16: 5 | F16: $15.25 - Gnocchi Porcini $12.50 - Spaghetti Bottarga $8.25 - Tagliatella Arrabbiata | G16: https://www.pastasisters.com/ | H16: 3343 W Pico Blvd, Los Angeles, CA 90019 | I16: http://www.youtube.com/watch?v=NHiqsrYkcuk | J16: 42673 | K16: yes | L16: 3
A17: =HYPERLINK("https://www.tokyodog.com/","CLOSED Tokyo Dog") -> CLOSED Tokyo Dog | B17: $2 Hot Dog Vs. $169 Hot Dog | C17: $$$ | D17: 1 | E17: 6 | F17: $169.00 - Juuni Ban | G17: https://www.tokyodog.com/ | H17: 2nd Ave &, Pike St, Seattle, WA 98111 | I17: http://www.youtube.com/watch?v=6R8n6FbXVc8 | J17: 42693 | K17: no | L17: 1
A18: =HYPERLINK("http://www.emeraldcityfishandchips.com/","Emerald City Fish & Chips") -> Emerald City Fish & Chips | B18: $8 Salmon vs $56 Salmon | C18: $ | D18: 1 | E18: 7 | F18: $8.25 - Salmon Fish & Chips | G18: http://www.emeraldcityfishandchips.com/ | H18: 3756 Rainier Ave S, Seattle, WA 98144 | I18: http://www.youtube.com/watch?v=6R8n6FbXVc8 | J18: 42693 | K18: no | L18: 2
A19: =HYPERLINK("https://www.ivars.com/locations/salmon-house","Ivar's Salmon House") -> Ivar's Salmon House | B19: $8 Salmon vs $56 Salmon | C19: $$ | D19: 1 | E19: 7 | F19: $25.00 - Chinook King Salmon | G19: https://www.ivars.com/locations/salmon-house | H19: 401 NE Northlake Way, Seattle, WA 98105 | I19: http://www.youtube.com/watch?v=6R8n6FbXVc8 | J19: 42693 | K19: no
A20: =HYPERLINK("https://viciousdogshotdogs.com/","Vicious Dogs") -> Vicious Dogs | B20: $2 Hot Dog Vs. $169 Hot Dog | C20: $ | D20: 1 | E20: 6 | F20: $2.00 - Kosher Dog $6.00 - Sweet & Spicy | G20: https://viciousdogshotdogs.com/ | H20: 5231 Lankershim Blvd, North Hollywood, CA 91601 | I20: http://www.youtube.com/watch?v=6R8n6FbXVc8 | J20: 42693 | K20: no
A21: =HYPERLINK("https://www.wurstkuche.com/","Wurstküche") -> Wurstküche | B21: $2 Hot Dog Vs. $169 Hot Dog | C21: $$ | D21: 1 | E21: 6 | F21: $8.50 - Lamb with Mediterranean Spices $8.50 - Rattlesnake & Rabbit | G21: https://www.wurstkuche.com/ | H21: 800 E 3rd St, Los Angeles, CA 90013 | I21: http://www.youtube.com/watch?v=6R8n6FbXVc8 | J21: 42693 | K21: yes | L21: 1
A22: =HYPERLINK("https://elgaucho.com/dine/aqua/","Aqua By El Gaucho") -> Aqua By El Gaucho | B22: $8 Salmon vs $56 Salmon | C22: $$$ | D22: 1 | E22: 7 | F22: $56.00 - King Salmon | G22: https://elgaucho.com/dine/aqua/ | H22: 2801 Alaskan Way, Seattle, WA 98121 | I22: http://www.youtube.com/watch?v=V9eeg8d9XEg | J22: 42708 | K22: no
A23: =HYPERLINK("https://chosungalbee.com/","Chosun Galbee") -> Chosun Galbee | B23: $24 Korean BBQ vs $346 Korean BBQ | C23: $$$ | D23: 1 | E23: 8 | F23: $345.91 - Korean BBQ | G23: https://chosungalbee.com/ | H23: 3330 W Olympic Blvd, Los Angeles, CA 90019 | I23: http://www.youtube.com/watch?v=GTXP2FzQS94 | J23: 42722 | K23: no | L23: 2 | M23: S6E3 starts here
A24: OO-KOOK | B24: $24 Korean BBQ vs $346 Korean BBQ | C24: $ | D24: 1 | E24: 8 | F24: $23.99 - Korean BBQ | G24: http://ookookkoreanbbq.top-cafes.com/ | H24: 3385 W 8th St, Los Angeles, CA 90005 | I24: http://www.youtube.com/watch?v=GTXP2FzQS94 | J24: 42722 | K24: no | L24: 1 | M24: Per person
A25: =HYPERLINK("https://quarterskbbq.com/","Quarters") -> Quarters | B25: $24 Korean BBQ vs $346 Korean BBQ | C25: $$ | D25: 1 | E25: 8 | F25: $65.44 - Korean BBQ | G25: https://quarterskbbq.com/ | H25: 3465 W 6th St, Los Angeles, CA 90020 | I25: http://www.youtube.com/watch?v=GTXP2FzQS94 | J25: 42722 | K25: no | L25: 1
A26: =HYPERLINK("https://www.bottegalouie.com/","Bottega Louie") -> Bottega Louie | B26: $27 Cake Vs. $1,120 Cake | C26: $$$ | D26: 1 | E26: 9 | F26: $1,120.00 - Custom Cake | G26: https://www.bottegalouie.com/ | H26: 700 S Grand Ave, Los Angeles, CA 90017 | I26: http://www.youtube.com/watch?v=n4bucphC9r4 | J26: 42743 | K26: no
A27: =HYPERLINK("http://www.portosbakery.com/","Porto's Bakery") -> Porto's Bakery | B27: $27 Cake Vs. $1,120 Cake | C27: $ | D27: 1 | E27: 9 | F27: $26.75 - Milk'n Berries Cake | G27: http://www.portosbakery.com/ | H27: 315 N Brand Blvd, Glendale, CA 91203 | I27: http://www.youtube.com/watch?v=n4bucphC9r4 | J27: 42743 | K27: yes | L27: 1 | M27: Entire cake
A28: =HYPERLINK("http://proofbakery.com/","Proof Bakery") -> Proof Bakery | B28: $27 Cake Vs. $1,120 Cake | C28: $$ | D28: 1 | E28: 9 | F28: $48.00 - Chocolate Espresso Cake | G28: http://proofbakery.com/ | H28: 3156 Glendale Blvd, Los Angeles, CA 90039 | I28: http://www.youtube.com/watch?v=n4bucphC9r4 | J28: 42743 | K28: no | L28: 1 | M28: Entire cake
A29: =HYPERLINK("http://birdiesla.com/","Birdies") -> Birdies | B29: $1 Donut Vs. $100 Donut | C29: $$$ | D29: 2 | E29: 1 | F29: $100.00 - Golden Donut | G29: http://birdiesla.com/ | H29: 314 W Olympic Blvd, Los Angeles, CA 90015 | I29: http://www.youtube.com/watch?v=0n89GZvmeXI | J29: 42806 | K29: no
A30: =HYPERLINK("https://www.blinkiesdonuts.com/","Blinkie's Donut Emporium") -> Blinkie's Donut Emporium | B30: $1 Donut Vs. $100 Donut | C30: $ | D30: 2 | E30: 1 | F30: $1.00 - Glazed Donut | G30: https://www.blinkiesdonuts.com/ | H30: 4884 Topanga Canyon Blvd, Woodland Hills, CA 91364 | I30: http://www.youtube.com/watch?v=0n89GZvmeXI | J30: 42806 | K30: no | L30: 3
A31: The Church Key [CLOSED] | B31: $1 Donut Vs. $100 Donut | C31: $$ | D31: 2 | E31: 1 | F31: $12.00 - Brioche Donuts | H31: 8730 Sunset Blvd, West Hollywood, CA 90069 | I31: http://www.youtube.com/watch?v=0n89GZvmeXI | J31: 42806 | K31: no | M31: 3 donuts on the plate
A32: =HYPERLINK("https://redrock.sclv.com/Dining/Feast-Buffet/Menu-Sp","Feast Buffet, Red Rock Casino") -> Feast Buffet, Red Rock Casino | B32: $7 Buffet Vs. $95 Buffet | C32: $ | D32: 2 | E32: 2 | F32: $8.99 - Buffet Food | G32: https://redrock.sclv.com/Dining/Feast-Buffet/Menu-Sp | H32: 11011 W Charleston Blvd, Las Vegas, NV 89135 | I32: http://www.youtube.com/watch?v=U61yzVVlUoE | J32: 42813 | K32: no
A33: =HYPERLINK("https://www.caesars.com/ballys-las-vegas/restaurants/sterling-brunch","The Sterling Brunch, BLT Steak at Bally's") -> The Sterling Brunch, BLT Steak at Bally's | B33: $7 Buffet Vs. $95 Buffet | C33: $$$ | D33: 2 | E33: 2 | F33: $95.00 - Buffet Food | G33: https://www.caesars.com/ballys-las-vegas/restaurants/sterling-brunch | H33: 3645 S Las Vegas Blvd, Las Vegas, NV 89109 | I33: http://www.youtube.com/watch?v=U61yzVVlUoE | J33: 42813 | K33: no | L33: 2
A34: =HYPERLINK("https://www.cosmopolitanlasvegas.com/restaurants/wicked-spoon","Wicked Spoon, The Cosmopolitan") -> Wicked Spoon, The Cosmopolitan | B34: $7 Buffet Vs. $95 Buffet | C34: $$ | D34: 2 | E34: 2 | F34: $49.00 - Buffet Food | G34: https://www.cosmopolitanlasvegas.com/restaurants/wicked-spoon | H34: The Chelsea Tower, 3708 S Las Vegas Blvd Level 2, Las Vegas, NV 89109 | I34: http://www.youtube.com/watch?v=U61yzVVlUoE | J34: 42813 | K34: no | L34: 1
A35: =HYPERLINK("http://www.guisados.co/","Guisados") -> Guisados | B35: $47 Taco Vs. $1 Taco | C35: $$ | D35: 2 | E35: 3 | F35: $2.75 - Calabacitas Mole Poblano Cochinita Pibil | G35: http://www.guisados.co/ | H35: 2100 East Cesar E Chavez Avenue, Los Angeles, CA 90033 | I35: http://www.youtube.com/watch?v=DWq_sSSWWSI | J35: 42820 | K35: no | L35: 2 | M35: Per taco
A36: =HYPERLINK("https://www.leostacostruck.com/","Leo's Taco Truck") -> Leo's Taco Truck | B36: $47 Taco Vs. $1 Taco | C36: $ | D36: 2 | E36: 3 | F36: $1.25 - Tacos Al Pastor | G36: https://www.leostacostruck.com/ | H36: 1515 South La Brea Ave, Los Angeles, CA 90019 | I36: http://www.youtube.com/watch?v=DWq_sSSWWSI | J36: 42820 | K36: yes | L36: 1 | M36: Per taco
A37: =HYPERLINK("https://www.cosmopolitanlasvegas.com/restaurants/rose-rabbit-lie","Rose. Rabbit. Lie") -> Rose. Rabbit. Lie | B37: $47 Taco Vs. $1 Taco | C37: $$$ | D37: 2 | E37: 3 | F37: $47.00 - Caviar Taco | G37: https://www.cosmopolitanlasvegas.com/restaurants/rose-rabbit-lie | H37: The Chelsea Tower, 3708 Las Vegas Blvd S Level 2, Las Vegas, NV 89109 | I37: http://www.youtube.com/watch?v=DWq_sSSWWSI | J37: 42820 | K37: no
A38: =HYPERLINK("https://www.fostersfreeze.com/","Foster's Freeze") -> Foster's Freeze | B38: $1 Ice Cream Vs. $1,000 Ice Cream | C38: $ | D38: 2 | E38: 4 | F38: $1.69 - Small Dipped Cone | G38: https://www.fostersfreeze.com/ | H38: 4967 Eagle Rock Blvd, Los Angeles, CA 90041 | I38: http://www.youtube.com/watch?v=rNuIOpfA2HA | J38: 42827 | K38: yes | L38: 1
A39: =HYPERLINK("www.scoopswestside.com/","Scoops") -> Scoops | B39: $1 Ice Cream Vs. $1,000 Ice Cream | C39: $$ | D39: 2 | E39: 4 | F39: $3.95 - One Scoop Brown Bread Maple Black Truffle | G39: www.scoopswestside.com/ | H39: 5105 York Blvd, Los Angeles, CA 90042 | I39: http://www.youtube.com/watch?v=rNuIOpfA2HA | J39: 42827 | K39: no | L39: 2
A40: =HYPERLINK("https://serendipity3.com/","Serendipity 3") -> Serendipity 3 | B40: $1 Ice Cream Vs. $1,000 Ice Cream | C40: $$$ | D40: 2 | E40: 4 | F40: $1,000.00 - Golden Opulence Sundae | G40: https://serendipity3.com/ | H40: 225 E 60th St, New York, NY 10022 | I40: http://www.youtube.com/watch?v=rNuIOpfA2HA | J40: 42827 | K40: no
...

Sheet Main
A1: Restaurant | B1: Featured in Episode: | C1: Price Point | D1: Season | E1: Episode | F1: Cost | G1: Item | H1: Video Link | I1: Publish Date | J1: Episode Name | K1: Chain? | L1: Restaurant Link | M1: Address | N1: City | O1: Country | P1: Adam | Q1: Andrew | R1: Steven | S1: Others | T1: Votes | U1: Notes
A2: =HYPERLINK("http://www.hamasakula.com/","Hamasaku") -> Hamasaku | B2: $3 Sushi Vs. $250 Sushi | C2: $$ | D2: 1 | E2: 1 | F2: 18 | G2: Kinmedai White Ponzu Nigiri Platter Cajun Crab Roll | H2: http://www.youtube.com/watch?v=2GZrPR5Ajrs | I2: 42631 | J2: =HYPERLINK(H2,B2) -> $3 Sushi Vs. $250 Sushi | K2: no | L2: =VLOOKUP(A2, Map!A:G,2) -> $5 Pizza Vs. $135 Pizza | M2: 11043 CA-2, Los Angeles, CA 90025 | N2: Los Angeles | O2: USA | U2: Price per plate
A3: Sasabune | B3: $3 Sushi Vs. $250 Sushi | C3: $$$ | D3: 1 | E3: 1 | F3: 250 | G3: Omakase | H3: http://www.youtube.com/watch?v=2GZrPR5Ajrs | I3: 42631 | J3: =HYPERLINK(H3,B3) -> $3 Sushi Vs. $250 Sushi | K3: yes | L3: =VLOOKUP(A3, Map!A:G,2) | M3: 101 N Brand Blvd UNIT 220, Glendale, CA 91023 | N3: Los Angeles | O3: USA | T3: * | U3: Dinner for two
A4: =HYPERLINK("https://sushistop.com/","Sushi Stop") -> Sushi Stop | B4: $3 Sushi Vs. $250 Sushi | C4: $ | D4: 1 | E4: 1 | F4: 2.95 | G4: Spciy Scallap Roll | H4: http://www.youtube.com/watch?v=2GZrPR5Ajrs | I4: 42631 | J4: =HYPERLINK(H4,B4) -> $3 Sushi Vs. $250 Sushi | K4: yes | L4: =VLOOKUP(A4, Map!A:G,2) | M4: 2218 Sawtelle Blvd, Los Angeles, CA 90064 | N4: Los Angeles | O4: USA | T4: *
A5: =HYPERLINK("https://sushistop.com/","Sushi Stop") -> Sushi Stop | B5: $3 Sushi Vs. $250 Sushi | C5: $ | D5: 1 | E5: 1 | F5: 2.95 | G5: Sweet Shrimp Nigiri | H5: http://www.youtube.com/watch?v=2GZrPR5Ajrs | I5: 42631 | J5: =HYPERLINK(H5,B5) -> $3 Sushi Vs. $250 Sushi | K5: yes | L5: =VLOOKUP(A5, Map!A:G,2) | M5: 2218 Sawtelle Blvd, Los Angeles, CA 90064 | N5: Los Angeles | O5: USA | T5: *
A6: =HYPERLINK("https://sushistop.com/","Sushi Stop") -> Sushi Stop | B6: $3 Sushi Vs. $250 Sushi | C6: $ | D6: 1 | E6: 1 | F6: 4 | G6: Bluefin Nigiri | H6: http://www.youtube.com/watch?v=2GZrPR5Ajrs | I6: 42631 | J6: =HYPERLINK(H6,B6) -> $3 Sushi Vs. $250 Sushi | K6: yes | L6: =VLOOKUP(A6, Map!A:G,2) | M6: 2218 Sawtelle Blvd, Los Angeles, CA 90064 | N6: Los Angeles | O6: USA | T6: *
A7: =HYPERLINK("https://sushistop.com/","Sushi Stop") -> Sushi Stop | B7: $3 Sushi Vs. $250 Sushi | C7: $ | D7: 1 | E7: 1 | F7: 6 | G7: Spanish Mackerel | H7: http://www.youtube.com/watch?v=2GZrPR5Ajrs | I7: 42631 | J7: =HYPERLINK(H7,B7) -> $3 Sushi Vs. $250 Sushi | K7: yes | L7: =VLOOKUP(A7, Map!A:G,2) | M7: 2218 Sawtelle Blvd, Los Angeles, CA 90064 | N7: Los Angeles | O7: USA | T7: *
A8: =HYPERLINK("https://www.caesars.com/paris-las-vegas/restaurants/burger-brasserie","Burger Brasserie") -> Burger Brasserie | B8: $4 Burger Vs. $777 Burger | C8: $$$ | D8: 1 | E8: 2 | F8: 777 | G8: 777 Burger | H8: http://www.youtube.com/watch?v=wduZHtRbSkY | I8: 42638 | J8: =HYPERLINK(H8,B8) -> $4 Burger Vs. $777 Burger | K8: no | L8: =VLOOKUP(A8, Map!A:G,2) -> $5 Pizza Vs. $135 Pizza | M8: 3655 S Las Vegas Blvd, Las Vegas, NV 89109 | N8: Las Vegas | O8: USA | T8: *
A9: =HYPERLINK("https://www.caesars.com/planet-hollywood/restaurants/ramsay","Gordon Ramsay Burger") -> Gordon Ramsay Burger | B9: $4 Burger Vs. $777 Burger | C9: $$ | D9: 1 | E9: 2 | F9: 18 | G9: Hog Burger | H9: http://www.youtube.com/watch?v=wduZHtRbSkY | I9: 42638 | J9: =HYPERLINK(H9,B9) -> $4 Burger Vs. $777 Burger | K9: no | L9: =VLOOKUP(A9, Map!A:G,2) -> $5 Pizza Vs. $135 Pizza | M9: 3667 S Las Vegas Blvd, Las Vegas, NV 89109 | N9: Las Vegas | O9: USA | T9: *
A10: =HYPERLINK("https://www.habitburger.com/","Habit Burger") -> Habit Burger | B10: $4 Burger Vs. $777 Burger | C10: $ | D10: 1 | E10: 2 | F10: 4.15 | G10: Double Charburger | H10: http://www.youtube.com/watch?v=wduZHtRbSkY | I10: 42638 | J10: =HYPERLINK(H10,B10) -> $4 Burger Vs. $777 Burger | K10: yes | L10: =VLOOKUP(A10, Map!A:G,2) -> $5 Pizza Vs. $135 Pizza | M10: 4830 Blue Diamond Rd, Las Vegas, NV 89139 | N10: Las Vegas | O10: USA
A11: =HYPERLINK("https://www.blazepizza.com/locations/los-angeles-usc/","Blaze Pizza") -> Blaze Pizza | B11: $5 Pizza Vs. $135 Pizza | C11: $ | D11: 1 | E11: 3 | F11: 5.25 | G11: Simple Pie | H11: http://www.youtube.com/watch?v=vzSfnduxNDg | I11: 42645 | J11: =HYPERLINK(H11,B11) -> $5 Pizza Vs. $135 Pizza | K11: yes | L11: =VLOOKUP(A11, Map!A:G,2) -> $5 Pizza Vs. $135 Pizza | M11: 667 E Colorado Blvd, Pasadena, CA 91101 | N11: Los Angeles | O11: USA
A12: =HYPERLINK("https://www.blazepizza.com/locations/los-angeles-usc/","Blaze Pizza") -> Blaze Pizza | B12: $5 Pizza Vs. $135 Pizza | C12: $ | D12: 1 | E12: 3 | F12: 7.95 | G12: Green Stripe | H12: http://www.youtube.com/watch?v=vzSfnduxNDg | I12: 42645 | J12: =HYPERLINK(H12,B12) -> $5 Pizza Vs. $135 Pizza | K12: yes | L12: =VLOOKUP(A12, Map!A:G,2) -> $5 Pizza Vs. $135 Pizza | M12: 667 E Colorado Blvd, Pasadena, CA 91101 | N12: Los Angeles | O12: USA
A13: =HYPERLINK("https://pizzeriamozza.com/","Pizzeria Mozza") -> Pizzeria Mozza | B13: $5 Pizza Vs. $135 Pizza | C13: $$ | D13: 1 | E13: 3 | F13: 23 | G13: Squash Blossoms | H13: http://www.youtube.com/watch?v=vzSfnduxNDg | I13: 42645 | J13: =HYPERLINK(H13,B13) -> $5 Pizza Vs. $135 Pizza | K13: no | L13: =VLOOKUP(A13, Map!A:G,2) -> $15 Spaghetti Vs. $143 Spaghetti | M13: 641 N Highland Ave, Los Angeles, CA 90036 | N13: Los Angeles | O13: USA | T13: **
A14: =HYPERLINK("www.wolfgangpuck.com/dining/spago/","Spago") -> Spago | B14: $5 Pizza Vs. $135 Pizza | C14: $$$ | D14: 1 | E14: 3 | F14: 135 | G14: Italian Summer Truffle | H14: http://www.youtube.com/watch?v=vzSfnduxNDg | I14: 42645 | J14: =HYPERLINK(H14,B14) -> $5 Pizza Vs. $135 Pizza | K14: no | L14: =VLOOKUP(A14, Map!A:G,2) | M14: 176 N Canon Dr, Beverly Hills, CA 90210 | N14: Los Angeles | O14: USA
A15: =HYPERLINK("http://wolfgangpuck.com/dining/cut-beverly-hills/","CUT") -> CUT | B15: $11 Steak Vs. $306 Steak | C15: $$$ | D15: 1 | E15: 4 | F15: 306 | G15: Japanese Pure Wagyu | H15: http://www.youtube.com/watch?v=Z5FoX3ju2J0 | I15: 42659 | J15: =HYPERLINK(H15,B15) -> $11 Steak Vs. $306 Steak | K15: no | L15: =VLOOKUP(A15, Map!A:G,2) -> $5 Pizza Vs. $135 Pizza | M15: 9500 Wilshire Blvd, Beverly Hills, CA 90212 | N15: Los Angeles | O15: USA | T15: *
A16: =HYPERLINK("https://www.patinagroup.com/nick-and-stefs-steakhouse-la","Nick & Stef's Steakhouse") -> Nick & Stef's Steakhouse | B16: $11 Steak Vs. $306 Steak | C16: $$ | D16: 1 | E16: 4 | F16: 72 | G16: Dry-Aged Rib Eye | H16: http://www.youtube.com/watch?v=Z5FoX3ju2J0 | I16: 42659 | J16: =HYPERLINK(H16,B16) -> $11 Steak Vs. $306 Steak | K16: no | L16: =VLOOKUP(A16, Map!A:G,2) -> $15 Spaghetti Vs. $143 Spaghetti | M16: 330 S Hope St, Los Angeles, CA 90071 | N16: Los Angeles | O16: USA | T16: *
A17: =HYPERLINK("https://unclejohnsdtla.com/","Uncle John's Cafe") -> Uncle John's Cafe | B17: $11 Steak Vs. $306 Steak | C17: $ | D17: 1 | E17: 4 | F17: 11 | G17: Steak and Eggs | H17: http://www.youtube.com/watch?v=Z5FoX3ju2J0 | I17: 42659 | J17: =HYPERLINK(H17,B17) -> $11 Steak Vs. $306 Steak | K17: no | L17: =VLOOKUP(A17, Map!A:G,2) | M17: 834 S Grand Ave, Los Angeles, CA 90017 | N17: Los Angeles | O17: USA | T17: *
A18: =HYPERLINK("http://lepetitparisla.com/","Le Petit Paris") -> Le Petit Paris | B18: $8 Pasta Vs. $100 Pasta | C18: $$$ | D18: 1 | E18: 5 | F18: 100 | G18: Flambeed White Truffle Pasta | H18: http://www.youtube.com/watch?v=NHiqsrYkcuk | I18: 42673 | J18: =HYPERLINK(H18,B18) -> $8 Pasta Vs. $100 Pasta | K18: no | L18: =VLOOKUP(A18, Map!A:G,2) -> $5 Pizza Vs. $135 Pizza | M18: 418 S Spring St, Los Angeles, CA 90013 | N18: Los Angeles | O18: USA
A19: =HYPERLINK("https://www.osteriamamma.com/","Osteria Mamma") -> Osteria Mamma | B19: $8 Pasta Vs. $100 Pasta | C19: $$ | D19: 1 | E19: 5 | F19: 19.25 | G19: Pappardelle All'anatra | H19: http://www.youtube.com/watch?v=NHiqsrYkcuk | I19: 42673 | J19: =HYPERLINK(H19,B19) -> $8 Pasta Vs. $100 Pasta | K19: no | L19: =VLOOKUP(A19, Map!A:G,2) -> $15 Spaghetti Vs. $143 Spaghetti | M19: 5732 Melrose Ave, Hollywood, CA 90004 | N19: Los Angeles | O19: USA
A20: =HYPERLINK("https://www.osteriamamma.com/","Osteria Mamma") -> Osteria Mamma | B20: $8 Pasta Vs. $100 Pasta | C20: $$ | D20: 1 | E20: 5 | F20: 19.75 | G20: Bigoli Neri Alla Bottarga | H20: http://www.youtube.com/watch?v=NHiqsrYkcuk | I20: 42673 | J20: =HYPERLINK(H20,B20) -> $8 Pasta Vs. $100 Pasta | K20: no | L20: =VLOOKUP(A20, Map!A:G,2) -> $15 Spaghetti Vs. $143 Spaghetti | M20: 5732 Melrose Ave, Hollywood, CA 90004 | N20: Los Angeles | O20: USA
A21: =HYPERLINK("https://www.pastasisters.com/","Pasta Sisters") -> Pasta Sisters | B21: $8 Pasta Vs. $100 Pasta | C21: $ | D21: 1 | E21: 5 | F21: 8.25 | G21: Tagliatella Arrabbiata | H21: http://www.youtube.com/watch?v=NHiqsrYkcuk | I21: 42673 | J21: =HYPERLINK(H21,B21) -> $8 Pasta Vs. $100 Pasta | K21: yes | L21: =VLOOKUP(A21, Map!A:G,2) -> $15 Spaghetti Vs. $143 Spaghetti | M21: 3343 W Pico Blvd, Los Angeles, CA 90019 | N21: Los Angeles | O21: USA | T21: ***
A22: =HYPERLINK("https://www.pastasisters.com/","Pasta Sisters") -> Pasta Sisters | B22: $8 Pasta Vs. $100 Pasta | C22: $ | D22: 1 | E22: 5 | F22: 12.5 | G22: Spaghetti Bottarga | H22: http://www.youtube.com/watch?v=NHiqsrYkcuk | I22: 42673 | J22: =HYPERLINK(H22,B22) -> $8 Pasta Vs. $100 Pasta | K22: yes | L22: =VLOOKUP(A22, Map!A:G,2) -> $15 Spaghetti Vs. $143 Spaghetti | M22: 3343 W Pico Blvd, Los Angeles, CA 90019 | N22: Los Angeles | O22: USA | T22: ***
A23: =HYPERLINK("https://www.pastasisters.com/","Pasta Sisters") -> Pasta Sisters | B23: $8 Pasta Vs. $100 Pasta | C23: $ | D23: 1 | E23: 5 | F23: 15.25 | G23: Gnocchi Porcini | H23: http://www.youtube.com/watch?v=NHiqsrYkcuk | I23: 42673 | J23: =HYPERLINK(H23,B23) -> $8 Pasta Vs. $100 Pasta | K23: yes | L23: =VLOOKUP(A23, Map!A:G,2) -> $15 Spaghetti Vs. $143 Spaghetti | M23: 3343 W Pico Blvd, Los Angeles, CA 90019 | N23: Los Angeles | O23: USA | T23: ***
A24: =HYPERLINK("https://www.tokyodog.com/","CLOSED Tokyo Dog") -> CLOSED Tokyo Dog | B24: $2 Hot Dog Vs. $169 Hot Dog | C24: $$$ | D24: 1 | E24: 6 | F24: 169 | G24: Juuni Ban | H24: http://www.youtube.com/watch?v=6R8n6FbXVc8 | I24: 42693 | J24: =HYPERLINK(H24,B24) -> $2 Hot Dog Vs. $169 Hot Dog | K24: no | L24: =VLOOKUP(A24, Map!A:G,2) -> $5 Pizza Vs. $135 Pizza | M24: 2nd Ave &, Pike St, Seattle, WA 98111 | N24: Seattle | O24: USA | T24: *
A25: =HYPERLINK("https://viciousdogshotdogs.com/","Vicious Dogs") -> Vicious Dogs | B25: $2 Hot Dog Vs. $169 Hot Dog | C25: $ | D25: 1 | E25: 6 | F25: 2 | G25: Kosher Dog | H25: http://www.youtube.com/watch?v=6R8n6FbXVc8 | I25: 42693 | J25: =HYPERLINK(H25,B25) -> $2 Hot Dog Vs. $169 Hot Dog | K25: no | L25: =VLOOKUP(A25, Map!A:G,2) | M25: 5231 Lankershim Blvd, North Hollywood, CA 91601 | N25: Los Angeles | O25: USA
A26: =HYPERLINK("https://viciousdogshotdogs.com/","Vicious Dogs") -> Vicious Dogs | B26: $2 Hot Dog Vs. $169 Hot Dog | C26: $ | D26: 1 | E26: 6 | F26: 6 | G26: Sweet & Spicy | H26: http://www.youtube.com/watch?v=6R8n6FbXVc8 | I26: 42693 | J26: =HYPERLINK(H26,B26) -> $2 Hot Dog Vs. $169 Hot Dog | K26: no | L26: =VLOOKUP(A26, Map!A:G,2) | M26: 5231 Lankershim Blvd, North Hollywood, CA 91601 | N26: Los Angeles | O26: USA
A27: =HYPERLINK("https://www.wurstkuche.com/","Wurstküche") -> Wurstküche | B27: $2 Hot Dog Vs. $169 Hot Dog | C27: $$ | D27: 1 | E27: 6 | F27: 8.5 | G27: Lamb with Mediterranean Spices | H27: http://www.youtube.com/watch?v=6R8n6FbXVc8 | I27: 42693 | J27: =HYPERLINK(H27,B27) -> $2 Hot Dog Vs. $169 Hot Dog | K27: yes | L27: =VLOOKUP(A27, Map!A:G,2) | M27: 800 E 3rd St, Los Angeles, CA 90013 | N27: Los Angeles | O27: USA | T27: *
A28: =HYPERLINK("https://www.wurstkuche.com/","Wurstküche") -> Wurstküche | B28: $2 Hot Dog Vs. $169 Hot Dog | C28: $$ | D28: 1 | E28: 6 | F28: 8.5 | G28: Rattlesnake & Rabbit | H28: http://www.youtube.com/watch?v=6R8n6FbXVc8 | I28: 42693 | J28: =HYPERLINK(H28,B28) -> $2 Hot Dog Vs. $169 Hot Dog | K28: yes | L28: =VLOOKUP(A28, Map!A:G,2) | M28: 800 E 3rd St, Los Angeles, CA 90013 | N28: Los Angeles | O28: USA | T28: *
A29: =HYPERLINK("https://elgaucho.com/dine/aqua/","Aqua By El Gaucho") -> Aqua By El Gaucho | B29: $8 Salmon vs $56 Salmon | C29: $$$ | D29: 1 | E29: 7 | F29: 56 | G29: King Salmon | H29: http://www.youtube.com/watch?v=V9eeg8d9XEg | I29: 42708 | J29: =HYPERLINK(H29,B29) -> $8 Salmon vs $56 Salmon | K29: no | L29: =VLOOKUP(A29, Map!A:G,2) -> #N/A | M29: 2801 Alaskan Way, Seattle, WA 98121 | N29: Seattle | O29: USA
A30: =HYPERLINK("http://www.emeraldcityfishandchips.com/","Emerald City Fish & Chips") -> Emerald City Fish & Chips | B30: $8 Salmon vs $56 Salmon | C30: $ | D30: 1 | E30: 7 | F30: 8.25 | G30: Salmon Fish & Chips | H30: http://www.youtube.com/watch?v=6R8n6FbXVc8 | I30: 42693 | J30: =HYPERLINK(H30,B30) -> $8 Salmon vs $56 Salmon | K30: no | L30: =VLOOKUP(A30, Map!A:G,2) -> $5 Pizza Vs. $135 Pizza | M30: 3756 Rainier Ave S, Seattle, WA 98144 | N30: Seattle | O30: USA | T30: **
A31: =HYPERLINK("https://www.ivars.com/locations/salmon-house","Ivar's Salmon House") -> Ivar's Salmon House | B31: $8 Salmon vs $56 Salmon | C31: $$ | D31: 1 | E31: 7 | F31: 25 | G31: Chinook King Salmon | H31: http://www.youtube.com/watch?v=6R8n6FbXVc8 | I31: 42693 | J31: =HYPERLINK(H31,B31) -> $8 Salmon vs $56 Salmon | K31: no | L31: =VLOOKUP(A31, Map!A:G,2) -> $5 Pizza Vs. $135 Pizza | M31: 401 NE Northlake Way, Seattle, WA 98105 | N31: Seattle | O31: USA
A32: =HYPERLINK("https://chosungalbee.com/","Chosun Galbee") -> Chosun Galbee | B32: $24 Korean BBQ vs $346 Korean BBQ | C32: $$$ | D32: 1 | E32: 8 | F32: 345.91 | G32: Korean BBQ | H32: http://www.youtube.com/watch?v=GTXP2FzQS94 | I32: 42722 | J32: =HYPERLINK(H32,B32) -> $24 Korean BBQ vs $346 Korean BBQ | K32: no | L32: =VLOOKUP(A32, Map!A:G,2) -> $5 Pizza Vs. $135 Pizza | M32: 3330 W Olympic Blvd, Los Angeles, CA 90019 | N32: Los Angeles | O32: USA | T32: ** | U32: S6E3 starts here
A33: OO-KOOK | B33: $24 Korean BBQ vs $346 Korean BBQ | C33: $ | D33: 1 | E33: 8 | F33: 23.99 | G33: Korean BBQ | H33: http://www.youtube.com/watch?v=GTXP2FzQS94 | I33: 42722 | J33: =HYPERLINK(H33,B33) -> $24 Korean BBQ vs $346 Korean BBQ | K33: no | L33: =VLOOKUP(A33, Map!A:G,2) -> $15 Spaghetti Vs. $143 Spaghetti | M33: 3385 W 8th St, Los Angeles, CA 90005 | N33: Los Angeles | O33: USA | T33: * | U33: Per person
A34: =HYPERLINK("https://quarterskbbq.com/","Quarters") -> Quarters | B34: $24 Korean BBQ vs $346 Korean BBQ | C34: $$ | D34: 1 | E34: 8 | F34: 65.44 | G34: Korean BBQ | H34: http://www.youtube.com/watch?v=GTXP2FzQS94 | I34: 42722 | J34: =HYPERLINK(H34,B34) -> $24 Korean BBQ vs $346 Korean BBQ | K34: no | L34: =VLOOKUP(A34, Map!A:G,2) | M34: 3465 W 6th St, Los Angeles, CA 90020 | N34: Los Angeles | O34: USA | T34: *
A35: =HYPERLINK("https://www.bottegalouie.com/","Bottega Louie") -> Bottega Louie | B35: $27 Cake Vs. $1,120 Cake | C35: $$$ | D35: 1 | E35: 9 | F35: 1120 | G35: Custom Cake | H35: http://www.youtube.com/watch?v=n4bucphC9r4 | I35: 42743 | J35: =HYPERLINK(H35,B35) -> $27 Cake Vs. $1,120 Cake | K35: no | L35: =VLOOKUP(A35, Map!A:G,2) -> $5 Pizza Vs. $135 Pizza | M35: 700 S Grand Ave, Los Angeles, CA 90017 | N35: Los Angeles | O35: USA
A36: =HYPERLINK("http://www.portosbakery.com/","Porto's Bakery") -> Porto's Bakery | B36: $27 Cake Vs. $1,120 Cake | C36: $ | D36: 1 | E36: 9 | F36: 26.75 | G36: Milk'n Berries Cake | H36: http://www.youtube.com/watch?v=n4bucphC9r4 | I36: 42743 | J36: =HYPERLINK(H36,B36) -> $27 Cake Vs. $1,120 Cake | K36: yes | L36: =VLOOKUP(A36, Map!A:G,2) -> $15 Spaghetti Vs. $143 Spaghetti | M36: 315 N Brand Blvd, Glendale, CA 91203 | N36: Los Angeles | O36: USA | T36: * | U36: Entire cake
A37: =HYPERLINK("http://proofbakery.com/","Proof Bakery") -> Proof Bakery | B37: $27 Cake Vs. $1,120 Cake | C37: $$ | D37: 1 | E37: 9 | F37: 48 | G37: Chocolate Espresso Cake | H37: http://www.youtube.com/watch?v=n4bucphC9r4 | I37: 42743 | J37: =HYPERLINK(H37,B37) -> $27 Cake Vs. $1,120 Cake | K37: no | L37: =VLOOKUP(A37, Map!A:G,2) | M37: 3156 Glendale Blvd, Los Angeles, CA 90039 | N37: Los Angeles | O37: USA | T37: * | U37: Entire cake
A38: =HYPERLINK("http://birdiesla.com/","Birdies") -> Birdies | B38: $1 Donut Vs. $100 Donut | C38: $$$ | D38: 2 | E38: 1 | F38: 100 | G38: Golden Donut | H38: http://www.youtube.com/watch?v=0n89GZvmeXI | I38: 42806 | J38: =HYPERLINK(H38,B38) -> $1 Donut Vs. $100 Donut | K38: no | L38: =VLOOKUP(A38, Map!A:G,2) -> #N/A | M38: 314 W Olympic Blvd, Los Angeles, CA 90015 | N38: Los Angeles | O38: USA
A39: =HYPERLINK("https://www.blinkiesdonuts.com/","Blinkie's Donut Emporium") -> Blinkie's Donut Emporium | B39: $1 Donut Vs. $100 Donut | C39: $ | D39: 2 | E39: 1 | F39: 1 | G39: Glazed Donut | H39: http://www.youtube.com/watch?v=0n89GZvmeXI | I39: 42806 | J39: =HYPERLINK(H39,B39) -> $1 Donut Vs. $100 Donut | K39: no | L39: =VLOOKUP(A39, Map!A:G,2) -> $5 Pizza Vs. $135 Pizza | M39: 4884 Topanga Canyon Blvd, Woodland Hills, CA 91364 | N39: Los Angeles | O39: USA | T39: ***
A40: The Church Key [CLOSED] | B40: $1 Donut Vs. $100 Donut | C40: $$ | D40: 2 | E40: 1 | F40: 12 | G40: Brioche Donuts | H40: http://www.youtube.com/watch?v=0n89GZvmeXI | I40: 42806 | J40: =HYPERLINK(H40,B40) -> $1 Donut Vs. $100 Donut | K40: no | L40: =VLOOKUP(A40, Map!A:G,2) | M40: 8730 Sunset Blvd, West Hollywood, CA 90069 | N40: Los Angeles | O40: USA | U40: 3 donuts on the plate
...

Sheet Read Me
A1: Here are some notes about this spreadsheet: Original credit goes to reddit user u/pauseforasecond, who created the first spreadsheet and posted it to the FoodNYC subreddit. I added a few more columns and added every episode that has been publiushed since the original spreadsheet was created. Map Sheet is formatted for importing into Google Maps, it's formatted so each row is a restaurant. It's the first sheet because Google Maps will only import the first sheet in a Google Sheet. The Google Map can be found here. Main Sheet is formatted so that each row is an item featured on the show (whether it was a main item, side trip, etc). All new entries have the Google Maps link instead of a link to a restaurant's website. I started to record which item got who's vote (not just how many votes), but I didn't go back through and do it for all the episodes. I really like the places that are featured in the Worth It videos, so I just wanted a quick and handy way to be able to see where they are if I'm ever in the vicinity of them.
